Workbook

Sheet Portada
B18: COSTO360 S.A.S.
B20: Desglose de Costos Operativo Mensual — Costos Directos, Indirectos, Precios Unitarios, Impuestos, Reservas y Margen de Beneficio
B24: Corte: septiembre de 2026
B27: Elaborado sobre datos reales investigados — ver notas de fuente en cada hoja. TRM asumida: $3.048,12 COP/USD (Banco de la Republica, referencia usada en el modelo financiero base).

Sheet Resumen Ejecutivo
C1: RESUMEN EJECUTIVO
C2: Costo360 S.A.S. — Corte: septiembre de 2026. Todas las cifras enlazadas por formula a la Hoja 07 (Estado de Resultados).
A5: Ingresos Mensuales | D5: Costos Directos (COGS) | G5: Margen Bruto ($) | J5: Margen Bruto (%)
A6: ='07_Estado_Resultados_PyG'!B5 -> 61810000 | D6: ='07_Estado_Resultados_PyG'!B6 -> 20644808 | G6: ='07_Estado_Resultados_PyG'!B7 -> 41165192 | J6: ='07_Estado_Resultados_PyG'!C7 -> 0.66599566
A9: Costos Indirectos (OpEx) | D9: EBITDA | G9: Impuestos y Tasas | J9: Reservas de Contingencia
A10: ='07_Estado_Resultados_PyG'!B8 -> 3599105 | D10: ='07_Estado_Resultados_PyG'!B9 -> 37566087 | G10: ='07_Estado_Resultados_PyG'!B11 -> 5252205.7 | J10: ='07_Estado_Resultados_PyG'!B10 -> 3655294.6
A13: Utilidad Neta Mensual ($) | D13: Utilidad Neta Mensual (%)
A14: ='07_Estado_Resultados_PyG'!B12 -> 28658587 | D14: ='07_Estado_Resultados_PyG'!C12 -> 0.46365615
A17: Analisis de Sensibilidad — 3 Escenarios de Crecimiento
A18: Arranque y Punto de Equilibrio usan la misma mezcla proporcional de planes que el Regimen Pleno (50 Starter : 42 Pro : 16 Enterprise), calculados por formula sobre los costos unitarios de la Hoja 02.
A20: Escenario | B20: # Talleres | C20: Starter | D20: Pro | E20: Enterprise | F20: Ingresos (COP) | G20: COGS (COP) | H20: Margen Bruto (COP) | I20: Margen Bruto (%)
A21: Arranque | B21: 15 | C21: =ROUND(B21*'02_Costos_Directos_COGS'!C19,0) -> 7 | D21: =ROUND(B21*'02_Costos_Directos_COGS'!C20,0) -> 6 | E21: =B21-C21-D21 -> 2 | F21: =C21*'02_Costos_Directos_COGS'!B5+D21*'02_Costos_Directos_COGS'!C5+E21*'02_Costos_Directos_COGS'!D5 -> 8120000 | G21: =C21*'02_Costos_Directos_COGS'!B11+D21*'02_Costos_Directos_COGS'!C11+E21*'02_Costos_Directos_COGS'!D11 -> 2667604 | H21: =F21-G21 -> 5452396 | I21: =H21/F21 -> 0.67147734
A22: Punto de equilibrio | B22: 45 | C22: =ROUND(B22*'02_Costos_Directos_COGS'!C19,0) -> 21 | D22: =ROUND(B22*'02_Costos_Directos_COGS'!C20,0) -> 18 | E22: =B22-C22-D22 -> 6 | F22: =C22*'02_Costos_Directos_COGS'!B5+D22*'02_Costos_Directos_COGS'!C5+E22*'02_Costos_Directos_COGS'!D5 -> 24360000 | G22: =C22*'02_Costos_Directos_COGS'!B11+D22*'02_Costos_Directos_COGS'!C11+E22*'02_Costos_Directos_COGS'!D11 -> 8002812 | H22: =F22-G22 -> 16357188 | I22: =H22/F22 -> 0.67147734
A23: Regimen pleno (108 talleres) | B23: ='02_Costos_Directos_COGS'!B22 -> 108 | C23: ='02_Costos_Directos_COGS'!B19 -> 50 | D23: ='02_Costos_Directos_COGS'!B20 -> 42 | E23: ='02_Costos_Directos_COGS'!B21 -> 16 | F23: ='02_Costos_Directos_COGS'!E22 -> 61810000 | G23: ='02_Costos_Directos_COGS'!G22 -> 20644808 | H23: ='02_Costos_Directos_COGS'!H22 -> 41165192 | I23: ='02_Costos_Directos_COGS'!I22 -> 0.66599566
A25: Fuente: docs/PLAN_COSTOS_COMPLETO_COSTO360.md (modelo financiero oficial, actualizado 2026-08-22). Ver Hoja 07 para el detalle completo del Estado de Resultados.

Sheet 02_Costos_Directos_COGS
A1: 02. COSTOS DIRECTOS DEL SERVICIO (COGS) — Costo Unitario por Plan
A2: Fuente: docs/PLAN_COSTOS_COMPLETO_COSTO360.md (modelo financiero oficial, actualizado 2026-08-22).
A4: Componente (costo unitario mensual, COP) | B4: Starter | C4: Pro | D4: Enterprise
A5: Precio mensual de suscripcion (PVP) | B5: 150000 | C5: 375000 | D5: 2410000
A6: Consumo IA producto "Cost" (Claude Sonnet 5 + Fable 100% + Gemini 3.1 Pro, 30 conv/mes/usuario) | B6: 0 | C6: 51124 | D6: 511240
A7: Agente de Atencion al Cliente | B7: 242 | C7: 242 | D7: 242
A8: Comision pasarela de pago (Wompi/ePayco, 2,99% + $900) | B8: =ROUND(B5*0.0299+900,0) -> 5385 | C8: =ROUND(C5*0.0299+900,0) -> 12113 | D8: =ROUND(D5*0.0299+900,0) -> 72959
A9: Infraestructura cloud prorrateada (Azure Container Apps + Supabase Pro + Vercel Pro + Resend) | B9: 2253 | C9: 25408 | D9: 233941
A10: Mano de obra directa (operacion de agentes por el fundador) | B10: 1566 | C10: 17671 | D10: 162685
A11: TOTAL COSTO DIRECTO UNITARIO (COGS) | B11: =SUM(B6:B10) -> 9446 | C11: =SUM(C6:C10) -> 106558 | D11: =SUM(D6:D10) -> 981067
A12: Margen bruto unitario % | B12: =(B5-B11)/B5 -> 0.93702667 | C12: =(C5-C11)/C5 -> 0.71584533 | D12: =(D5-D11)/D5 -> 0.59291826
A14: Comision pasarela de pago calculada con formula = precio*2,99% + $900 (Wompi/ePayco).
A16: Simulacion consolidada — 108 talleres activos (escala de regimen pleno)
A18: Plan | B18: Cantidad | C18: % Mezcla | D18: Precio Unitario | E18: Ingresos | F18: COGS Unitario | G18: COGS Total | H18: Margen Bruto $ | I18: Margen Bruto %
A19: Starter | B19: 50 | C19: =B19/$B$22 -> 0.46296296 | D19: =B5 -> 150000 | E19: =B19*D19 -> 7500000 | F19: =B11 -> 9446 | G19: =B19*F19 -> 472300 | H19: =E19-G19 -> 7027700 | I19: =H19/E19 -> 0.93702667
A20: Pro | B20: 42 | C20: =B20/$B$22 -> 0.38888889 | D20: =C5 -> 375000 | E20: =B20*D20 -> 15750000 | F20: =C11 -> 106558 | G20: =B20*F20 -> 4475436 | H20: =E20-G20 -> 11274564 | I20: =H20/E20 -> 0.71584533
A21: Enterprise | B21: 16 | C21: =B21/$B$22 -> 0.14814815 | D21: =D5 -> 2410000 | E21: =B21*D21 -> 38560000 | F21: =D11 -> 981067 | G21: =B21*F21 -> 15697072 | H21: =E21-G21 -> 22862928 | I21: =H21/E21 -> 0.59291826
A22: TOTAL | B22: =SUM(B19:B21) -> 108 | C22: =SUM(C19:C21) -> 1 | D22: — | E22: =SUM(E19:E21) -> 61810000 | F22: — | G22: =SUM(G19:G21) -> 20644808 | H22: =SUM(H19:H21) -> 41165192 | I22: =H22/E22 -> 0.66599566
A24: Fuente: docs/PLAN_COSTOS_COMPLETO_COSTO360.md (modelo financiero oficial, actualizado 2026-08-22). Mezcla 108 talleres: 50 Starter + 42 Pro + 16 Enterprise.

Sheet 03_Precios_Unitarios_Cantidades
A1: 03. PRECIOS UNITARIOS x CANTIDADES — Trazabilidad de Costos (Cost Breakdown Structure)
A2: De donde sale cada peso del COGS: cada fila reconstruye el total de la Hoja 02 a partir de precio unitario x cantidad/mes (escenario 108 talleres).
A4: Componente | B4: Unidad de medida | C4: Precio Unitario (COP) | D4: Cantidad/mes (108 talleres) | E4: Subtotal mensual (COP)
A5: Consumo IA producto "Cost" (Claude Sonnet 5 + Fable 100% + Gemini 3.1 Pro) | B5: Por usuario con acceso al producto/mes (1 usuario/taller en Starter-Pro, 10 usuarios/taller en Enterprise — supuesto) | C5: ='02_Costos_Directos_COGS'!C6 -> 51124 | D5: ='02_Costos_Directos_COGS'!B20*1+'02_Costos_Directos_COGS'!B21*10 -> 202 | E5: =C5*D5 -> 10327048
A6: Agente de Atencion al Cliente | B6: Por taller/mes (tarifa plana, todos los planes) | C6: ='02_Costos_Directos_COGS'!B7 -> 242 | D6: ='02_Costos_Directos_COGS'!B22 -> 108 | E6: =C6*D6 -> 26136
A7: Comision pasarela de pago (Wompi/ePayco, 2,99% + $900) | B7: Por transaccion de cobro/taller/mes (precio unitario promedio ponderado por mezcla de planes) | C7: =('02_Costos_Directos_COGS'!B8*'02_Costos_Directos_COGS'!B19+'02_Costos_Directos_COGS'!C8*'02_Costos_Directos_COGS'!B20+'02_Costos_Directos_COGS'!D8*'02_Costos_Directos_COGS'!B21)/D7 -> 18012.407 | D7: ='02_Costos_Directos_COGS'!B22 -> 108 | E7: =C7*D7 -> 1945340
A8: Infraestructura cloud prorrateada (Azure Container Apps + Supabase Pro + Vercel Pro + Resend) | B8: Por taller/mes (precio unitario promedio ponderado por mezcla de planes) | C8: =('02_Costos_Directos_COGS'!B9*'02_Costos_Directos_COGS'!B19+'02_Costos_Directos_COGS'!C9*'02_Costos_Directos_COGS'!B20+'02_Costos_Directos_COGS'!D9*'02_Costos_Directos_COGS'!B21)/D8 -> 45581.87 | D8: ='02_Costos_Directos_COGS'!B22 -> 108 | E8: =C8*D8 -> 4922842
A9: Mano de obra directa (operacion de agentes por el fundador) | B9: Por taller/mes (precio unitario promedio ponderado por mezcla de planes) | C9: =('02_Costos_Directos_COGS'!B10*'02_Costos_Directos_COGS'!B19+'02_Costos_Directos_COGS'!C10*'02_Costos_Directos_COGS'!B20+'02_Costos_Directos_COGS'!D10*'02_Costos_Directos_COGS'!B21)/D9 -> 31698.537 | D9: ='02_Costos_Directos_COGS'!B22 -> 108 | E9: =C9*D9 -> 3423442
A10: TOTAL COGS (trazado componente por componente) | E10: =SUM(E5:E9) -> 20644808
A11: Verificacion vs. Hoja 02 (debe ser 0) | E11: =E10-'02_Costos_Directos_COGS'!G22 -> 0
A13: Fuente: docs/PLAN_COSTOS_COMPLETO_COSTO360.md (modelo financiero oficial, actualizado 2026-08-22).

Sheet 04_Costos_Indirectos_OpEx
A1: 04. COSTOS INDIRECTOS (OpEx) — Gastos Fijos Mensuales de Operacion
A2: Costos fijos que NO escalan con la cantidad de talleres activos.
A4: Rubro | B4: Proveedor | C4: Costo mensual (COP) | D4: Justificacion
A5: Asesoria legal externa | B5: Legal Help / firma boutique | C5: 655401 | D5: Plan "departamento legal externo", $550.758 + IVA 19%
A6: Asesoria contable y tributaria | B6: Contador titulado externo | C6: 300000 | D6: Declaraciones DIAN, conciliacion, balances
A7: Claude Max (20x) | B7: Anthropic PBC | C7: 630000 | D7: Entorno de desarrollo continuo del fundador
A8: Google AI Ultra | B8: Google | C8: 630000 | D8: Investigacion y multimodalidad para desarrollo
A9: Microsoft 365 Business Premium | B9: Microsoft | C9: 67059 | D9: Correo corporativo + seguridad Defender
A10: Marketing y publicidad (pauta paga) | B10: LinkedIn/Google Ads | C10: 500000 | D10: Campanas B2B sector construccion
A11: Diseno y contenido | B11: Canva Pro / Buffer | C11: 60000 | D11: Contenido de marca en redes
A12: Otros gastos administrativos (colchon) | B12: — | C12: 756645 | D12: Colchon documentado en el modelo oficial para imprevistos administrativos menores no descritos linea por linea
A13: TOTAL COSTOS INDIRECTOS (OpEx) | C13: =SUM(C5:C12) -> 3599105
A15: Fuente: docs/PLAN_COSTOS_COMPLETO_COSTO360.md (modelo financiero oficial, actualizado 2026-08-22).

Sheet 05_Impuestos_y_Tasas
A1: 05. IMPUESTOS Y TASAS — Regimen Simple de Tributacion (RST), Colombia
A2: Impacto mensual calculado sobre el escenario de 108 talleres activos (Hoja 02).
A4: Tributo | B4: Autoridad | C4: Tarifa | D4: Base | E4: Impacto mensual (COP) | F4: Nota
A5: Regimen Simple de Tributacion (RST) | B5: DIAN | C5: 0.083 | D5: Ingresos brutos | E5: ='02_Costos_Directos_COGS'!E22*C5 -> 5130230 | F5: Unifica renta + ICA + aportes en un solo pago, reemplaza el 35% de renta ordinaria
A6: Industria y Comercio (ICA) | B6: Distrito/municipio | C6: 0.00966 | D6: Ingresos brutos en la ciudad | E6: Incluido en el RST | F6: Absorbido dentro de la tarifa unificada; no suma aparte al total
A7: IVA (informativo — no es un costo real de la empresa) | B7: DIAN | C7: 0.19 | D7: Facturacion a talleres | E7: ='02_Costos_Directos_COGS'!E22*C7 -> 11743900 | F7: Se recauda del cliente y se traslada a la DIAN — pass-through, NO reduce la utilidad de Costo360 ni suma al total de impuestos a cargo
A8: Retencion en la fuente | B8: Clientes/DIAN | C8: 0 | D8: — | E8: 0 | F8: Exento: las sociedades bajo RST no sufren retefuente de sus clientes
A9: Gravamen a los Movimientos Financieros (GMF, 4x1000) | B9: Bancos/DIAN | C9: 0.004 | D9: Pagos a proveedores (COGS+OpEx) | E9: =('02_Costos_Directos_COGS'!G22+'04_Costos_Indirectos_OpEx'!C13)*C9 -> 96975.652 | F9: Sobre transferencias para pagar servidores, APIs, honorarios
A10: Renovacion registro mercantil | B10: Camara de Comercio | C10: Mensualizado | D10: — | E10: 25000 | F10: Cuota mensualizada de la renovacion anual
A11: TOTAL CARGA TRIBUTARIA DIRECTA (excluye IVA pass-through) | C11: =E11/'02_Costos_Directos_COGS'!E22 -> 0.084973397 | E11: =E5+E9+E10+E8 -> 5252205.7 | F11: Este es el numero que si resta a la utilidad
A13: Fuente: docs/PLAN_COSTOS_COMPLETO_COSTO360.md (modelo financiero oficial, actualizado 2026-08-22).

Sheet 06_Reservas_Contingencia
A1: 06. RESERVAS DE CONTINGENCIA — Metodologia PMI (Riesgos Cuantificables del Negocio)
A2: Reserva de contingencia sobre riesgos identificables y cuantificables propios de la operacion de Costo360.
A4: Codigo | B4: Concepto | C4: % / Factor | D4: Base de calculo | E4: Monto mensual (COP) | F4: Objetivo
A5: RES-01 | B5: Colchon de volatilidad en consumo de IA | C5: 0.15 | D5: Consumo de IA producto en planes Pro+Enterprise | E5: =('02_Costos_Directos_COGS'!C6*'02_Costos_Directos_COGS'!B20+'02_Costos_Directos_COGS'!D6*'02_Costos_Directos_COGS'!B21)*C5 -> 1549057.2 | F5: Amortigua picos de uso imprevisto
A6: RES-02 | B6: Contingencia de escalamiento cloud/servidores | C6: 0.05 | D6: OpEx total | E6: ='04_Costos_Indirectos_OpEx'!C13*C6 -> 179955.25 | F6: Fondo para escalar Azure/Vercel ante trafico extraordinario
A7: RES-03 | B7: Provision de cartera morosa / churn | C7: 0.03 | D7: Ingresos brutos | E7: ='02_Costos_Directos_COGS'!E22*C7 -> 1854300 | F7: Reserva por mora de pago o cancelaciones
A8: RES-04 | B8: Fondo discrecional de soporte | C8: 0.02 | D8: OpEx total | E8: ='04_Costos_Indirectos_OpEx'!C13*C8 -> 71982.1 | F8: Caja menor para imprevistos operativos
A9: TOTAL | B9: RESERVAS | C9: =E9/'02_Costos_Directos_COGS'!E22 -> 0.059137592 | E9: =SUM(E5:E8) -> 3655294.6
A11: Fuente: docs/PLAN_COSTOS_COMPLETO_COSTO360.md (modelo financiero oficial, actualizado 2026-08-22).

Sheet 07_Estado_Resultados_PyG
A1: 07. ESTADO DE RESULTADOS (P&G) — Escenario 108 Talleres Activos
A2: Todas las cifras enlazadas por formula a las hojas 02, 04, 05 y 06. Ninguna cifra fue pegada a mano.
A4: Concepto | B4: COP | C4: % sobre Ingresos
A5: 1.0 Ingresos Operacionales Brutos | B5: ='02_Costos_Directos_COGS'!E22 -> 61810000
A6: 2.0 (-) Costos Directos del Servicio — COGS | B6: ='02_Costos_Directos_COGS'!G22 -> 20644808
A7: 3.0 (=) Utilidad Bruta / Margen Bruto | B7: =B5-B6 -> 41165192 | C7: =B7/B$5 -> 0.66599566
A8: 4.0 (-) Costos Indirectos — OpEx | B8: ='04_Costos_Indirectos_OpEx'!C13 -> 3599105
A9: 5.0 (=) EBITDA Operativo Mensual | B9: =B7-B8 -> 37566087 | C9: =B9/B$5 -> 0.60776714
A10: 6.0 (-) Reservas de Contingencia | B10: ='06_Reservas_Contingencia'!E9 -> 3655294.6
A11: 7.0 (-) Impuestos y Tasas directas (excl. IVA pass-through) | B11: ='05_Impuestos_y_Tasas'!E11 -> 5252205.7
A12: 8.0 (=) UTILIDAD NETA MENSUAL — Margen de Beneficio Final | B12: =B9-B10-B11 -> 28658587 | C12: =B12/B$5 -> 0.46365615
A14: Fuente: docs/PLAN_COSTOS_COMPLETO_COSTO360.md (modelo financiero oficial, actualizado 2026-08-22).

Sheet 08_Actualizacion_Operativa
A1: 08. ACTUALIZACION OPERATIVA — Septiembre 2026
A2: El modelo financiero oficial (agosto 2026) no incluye 2 funciones reales lanzadas en septiembre 2026: Render de cocina con IA (OpenAI) y Voz de Cost (ElevenLabs). Esta hoja muestra el impacto real de mantenerlas operando, sin alterar el modelo oficial de las hojas anteriores.
A5: Funcion nueva (no incluida en el modelo oficial) | B5: Costo unitario | C5: Aplica a | D5: Cantidad/mes | E5: Costo total mensual (COP)
A6: Render de cocina con IA (OpenAI, gpt-image-2.5-sunburst) | B6: 60962 | C6: Talleres Pro + Enterprise (cotizan proyectos de cocina con clientes reales — supuesto explicito) | D6: ='02_Costos_Directos_COGS'!B20+'02_Costos_Directos_COGS'!B21 -> 58 | E6: =B6*D6 -> 3535796
A7: Voz de Cost (ElevenLabs) | B7: 0 | C7: Cuenta actual en plan gratuito, 10.000 creditos/mes (~10 min de audio) | D7: — | E7: 0
A8: Nota Voz de Cost: si el uso supera el plan gratuito, el siguiente escalon (Starter, 30.000 creditos) cuesta 6 USD/mes ~ 18.289 COP/mes — reevaluar cuando haya datos reales de consumo.
A10: Costo adicional total no incluido en el modelo oficial (COP/mes) | E10: =E6+E7 -> 3535796
A13: Estado de Resultados — Modelo Oficial vs. Modelo Actualizado (con funciones de septiembre)
A15: Concepto | B15: Modelo Oficial (COP) | C15: Modelo Actualizado (COP) | D15: Diferencia vs. Oficial (COP)
A16: 1.0 Ingresos Operacionales Brutos | B16: ='07_Estado_Resultados_PyG'!B5 -> 61810000 | C16: =B16 -> 61810000 | D16: =C16-B16 -> 0
A17: 2.0 (-) Costos Directos del Servicio — COGS | B17: ='07_Estado_Resultados_PyG'!B6 -> 20644808 | C17: =B17+E10 -> 24180604 | D17: =C17-B17 -> 3535796
A18: 3.0 (=) Utilidad Bruta / Margen Bruto | B18: =B16-B17 -> 41165192 | C18: =C16-C17 -> 37629396 | D18: =C18-B18 -> -3535796
A19: 4.0 (-) Costos Indirectos — OpEx | B19: ='07_Estado_Resultados_PyG'!B8 -> 3599105 | C19: =B19 -> 3599105 | D19: =C19-B19 -> 0
A20: 5.0 (=) EBITDA Operativo Mensual | B20: =B18-B19 -> 37566087 | C20: =C18-C19 -> 34030291 | D20: =C20-B20 -> -3535796
A21: 6.0 (-) Reservas de Contingencia | B21: ='07_Estado_Resultados_PyG'!B10 -> 3655294.6 | C21: =B21 -> 3655294.6 | D21: =C21-B21 -> 0
A22: Auxiliar: GMF (4x1000) recalculado sobre COGS+OpEx actualizado | C22: =(C17+C19)*'05_Impuestos_y_Tasas'!C9 -> 111118.84
A23: 7.0 (-) Impuestos y Tasas directas (excl. IVA pass-through) | B23: ='07_Estado_Resultados_PyG'!B11 -> 5252205.7 | C23: ='05_Impuestos_y_Tasas'!E5+C22+'05_Impuestos_y_Tasas'!E10+'05_Impuestos_y_Tasas'!E8 -> 5266348.8 | D23: =C23-B23 -> 14143.184
A24: 8.0 (=) UTILIDAD NETA MENSUAL | B24: =B20-B21-B23 -> 28658587 | C24: =C20-C21-C23 -> 25108648 | D24: =C24-B24 -> -3549939.2
A26: Diferencia vs. modelo oficial (COP/mes) | B26: =D24 -> -3549939.2
A28: Hallazgo real a vigilar: compresion de margen en el plan Pro
A29: Plan | B29: Margen bruto unitario oficial | C29: Margen bruto unitario con render de cocina | D29: Variacion (pp)
A30: Pro | B30: ='02_Costos_Directos_COGS'!C12 -> 0.71584533 | C30: =('02_Costos_Directos_COGS'!C5-('02_Costos_Directos_COGS'!C11+B6))/'02_Costos_Directos_COGS'!C5 -> 0.55328 | D30: =C30-B30 -> -0.16256533
A32: El render de cocina, aunque valioso comercialmente, comprime el margen bruto unitario del plan Pro de ~71,6% a ~55,3%. Se recomienda vigilar este indicador y evaluar un cobro adicional o un tope de uso por taller.
A34: Fuente: backend/services/render_service.py (tope $20 USD/taller/mes), backend/.env (TRM $3.048,12 COP/USD), plan gratuito ElevenLabs.

Sheet 09_Simulacion_Consumo_Exagerado
A1: SIMULACION DE CONSUMO EXAGERADO POR API — EMPRESA GRANDE (ENTERPRISE, 10 USUARIOS)
A2: Techo de seguridad de consumo real, no el gasto esperado — para dimensionar colchon de creditos y evitar que un cliente grande se quede sin servicio a fin de mes.
A4: Tabla 1 — Agente conversacional "Cost" (Claude Sonnet 5 + Fable 100% + Gemini 3.1 Pro 100%)
A6: Escenario | B6: Conversaciones/mes/usuario | C6: Tokens entrada/salida por conversacion | D6: Costo por usuario/mes (COP) | E6: Costo empresa completa (10 usuarios)
A7: Normal (modelo oficial, docs/PLAN_COSTOS_COMPLETO_COSTO360.md) | B7: 30 | C7: 24.500 / 1.500 | D7: ='02_Costos_Directos_COGS'!C6 -> 51124 | E7: ='02_Costos_Directos_COGS'!D6 -> 511240
A8: Exagerado (8 conversaciones/dia habil x 22 dias habiles/mes; proyectos mas complejos, ~2x turnos) | B8: =8*22 -> 176 | C8: ~49.000 / 3.000 | D8: ='02_Costos_Directos_COGS'!C6*B14 -> 599854.93 | E8: =D8*10 -> 5998549.3
A10: Derivacion del factor de intensidad (exagerado vs. normal) — celdas auditables
A11: Factor | B11: Valor
A12: Frecuencia (conversaciones exageradas / conversaciones normal) | B12: =B8/B7 -> 5.8666667
A13: Complejidad (turnos y tokens ~2x mas largos por proyecto complejo — supuesto) | B13: 2
A14: Factor total de intensidad (frecuencia x complejidad) | B14: =B12*B13 -> 11.733333
A16: Fuente: docs/PLAN_COSTOS_COMPLETO_COSTO360.md (consumo normal) y estimacion propia del fundador para el escenario exagerado (2026-09-16).
A18: Tabla 2 — Render de cocina con IA (OpenAI gpt-image-2.5-sunburst)
A20: Escenario | B20: Renders/mes | C20: Costo (USD) | D20: Costo (COP, TRM 3.048,12) | E20: Dentro del tope actual
A21: Tope actual configurado (backend/services/render_service.py) | B21: 400 | C21: 20 | D21: ='08_Actualizacion_Operativa'!B6 -> 60962 | E21: — es el techo duro
A22: Exagerado (60 cotizaciones/mes x 3 renders c/u) | B22: =60*3 -> 180 | C22: =(C21/B21)*B22 -> 9 | D22: =(D21/C21)*C22 -> 27432.9 | E22: ="Si, con margen de sobra (queda al "&TEXT(B22/B21,"0%")&" del tope)" -> Si, con margen de sobra (queda al 45% del tope)
A23: A diferencia de las otras 2 APIs, esta ya tiene un tope aislado POR EMPRESA en el propio codigo — un cliente grande nunca puede afectar a otros clientes. No requiere ajuste.
A25: Fuente: backend/services/render_service.py (tope de $20 USD/taller/mes) y Hoja 08 (TRM 3.048,12 COP/USD).
A27: Derivacion del consumo exagerado — Voz de Cost (celdas auditables)
A28: Variable | B28: Valor
A29: Interacciones/dia habil (hablar + escuchar) | B29: 5
A30: Dias habiles/mes | B30: 22
A31: Segundos de audio por interaccion | B31: 35
A32: Creditos del plan actual (gratuito) | B32: 10000
A33: Minutos de audio incluidos en el plan actual | B33: 10
A34: Interacciones/mes/usuario | B34: =B29*B30 -> 110
A35: Segundos de audio/mes/usuario | B35: =B34*B31 -> 3850
A36: Creditos por segundo de audio (plan actual) | B36: =B32/(B33*60) -> 16.666667
A37: Creditos exagerados/usuario/mes | B37: =B35*B36 -> 64166.667
A39: Tabla 3 — Voz de Cost (ElevenLabs: hablar + escuchar) — EL HALLAZGO CRITICO
A41: Concepto | B41: Valor
A42: Plan actual | B42: 10.000 creditos/mes (~10 minutos de audio)
A43: Alcance del plan actual | B43: Una sola cuenta/API key COMPARTIDA por TODOS los clientes de Costo360 — no hay aislamiento por empresa como en OpenAI
A44: Consumo exagerado por usuario (5 interacciones/dia habil x 22 dias; ~35 seg de audio por interaccion) | B44: =B37 -> 64166.667
A45: Consumo exagerado, 1 empresa grande (10 usuarios) | B45: =B44*10 -> 641666.67
A46: Veces que excede el plan actual | B46: =B45/B32 -> 64.166667
A47: Tiempo hasta agotar el credito de TODOS los clientes de Costo360 si una sola empresa grande usa la voz intensivamente (dias habiles) | B47: =(B32/B45)*B30 -> 0.34285714
A48: Plan ElevenLabs "Starter" (30.000 creditos, $6 USD/mes) — cobertura de la necesidad exagerada | B48: =30000/B45 -> 0.046753247
A49: Plan ElevenLabs "Creator" (121.000 creditos, $22 USD/mes) — cobertura de la necesidad exagerada | B49: =121000/B45 -> 0.18857143
A51: RECOMENDACION: antes de vender Costo360 a empresas grandes, Voz de Cost necesita (a) un tope de consumo por empresa igual al que ya tiene el render de cocina, y/o (b) migrar a un plan de ElevenLabs por volumen/uso, para que un solo cliente grande no deje sin voz a los demas clientes de la plataforma. Esto es un hallazgo operativo, no una funcionalidad rota hoy — el riesgo aparece recien cuando haya clientes grandes reales usando la voz activamente.
...

Sheet 10_Glosario_de_Terminos
A1: GLOSARIO — TERMINOS DEL DESGLOSE DE COSTOS DE COSTO360
A2: Explicacion en lenguaje simple de cada termino tecnico, financiero y tributario usado en este libro
A4: Termino | B4: Explicacion
A5: A. La estructura basica (de donde sale la plata)
A6: Costos Directos (COGS) | B6: Lo que le cuesta a Costo360, exactamente, atender a UN taller mas. Si manana se suma un cliente nuevo, estos son los unicos costos que suben automaticamente con el (consumo de IA, comision de la pasarela de pago, infraestructura que usa ese cliente). Es "costo variable": crece con la cantidad de clientes.
A7: Costos Indirectos / Gastos Generales (OpEx) | B7: Lo que Costo360 paga para existir como empresa, sin importar si tiene 1 cliente o 100 (abogado, contador, herramientas del fundador, marketing). Es "costo fijo": no cambia mes a mes con la cantidad de talleres.
A8: Margen Bruto | B8: Ingresos menos Costos Directos. Responde: "de cada peso que factura un taller, cuanto le queda a Costo360 despues de servirlo, antes de pagar gastos administrativos". Se muestra en pesos y en porcentaje.
A9: EBITDA | B9: Margen Bruto menos Gastos Generales (OpEx). Es la ganancia operativa pura del negocio, antes de reservas e impuestos.
A10: Utilidad Neta / Margen de Beneficio | B10: Lo que realmente queda al final, despues de restarle al EBITDA las reservas de contingencia y los impuestos. Es la plata real disponible para el fundador o para reinvertir.
A11: B. Precios y cantidades (la receta de cada costo)
A12: Precio Unitario | B12: Cuanto cuesta UNA unidad de algo (una conversacion con Cost, un render, un usuario). Multiplicado por la Cantidad (cuantas unidades se consumen al mes) da el costo total de ese item.
A13: PVP (Precio de Venta al Publico) | B13: Lo que le cobra Costo360 al taller por su suscripcion mensual.
A14: Prorrateo | B14: Repartir un costo fijo (ej. el salario del fundador, o el servidor compartido) entre los distintos planes de forma proporcional a cuanto usa cada uno realmente, no por igual.
A15: TRM (Tasa Representativa del Mercado) | B15: El tipo de cambio oficial peso colombiano/dolar del Banco de la Republica. Se usa como referencia fija ($3.048,12 COP/USD) para convertir a pesos los costos de APIs cobrados en dolares.
A16: C. Impuestos y tasas (lo que se le paga al Estado)
A17: RST (Regimen Simple de Tributacion) | B17: Un regimen tributario colombiano para empresas pequenas/medianas: en vez de pagar por separado Renta + Industria y Comercio + otros aportes, se paga UN solo porcentaje sobre los ingresos brutos (8,3% en Costo360).
A18: ICA (Industria y Comercio) | B18: Impuesto municipal/distrital sobre los ingresos de una empresa. Bajo el RST queda absorbido dentro del 8,3% de arriba, no se paga aparte.
A19: IVA (19%) | B19: El impuesto que se le cobra al cliente final sobre la venta. No es una ganancia ni un costo real de Costo360 — se recauda del taller y se le entrega integro a la DIAN. Por eso se muestra aparte, como "pass-through".
A20: Retencion en la Fuente | B20: Un anticipo de impuestos que normalmente un cliente le descuenta a su proveedor antes de pagarle. Las empresas bajo RST estan exentas de esto.
A21: GMF / 4x1000 | B21: Impuesto del 0,4% que cobran los bancos sobre movimientos de dinero (ej. cuando Costo360 le paga a un proveedor).
A22: D. Reservas y riesgo (el colchon)
A23: Reserva de Contingencia | B23: Plata que se aparta cada mes, de forma preventiva, para riesgos que se pueden anticipar aunque no se sepa cuando van a pasar. Es dinero que se guarda "por si acaso", no un gasto garantizado.
A24: Colchon / Techo de seguridad | B24: Un margen extra sumado a un calculo esperado para no quedarse corto si la realidad es peor de lo previsto.
A25: Cartera Morosa / Churn | B25: "Morosa" = clientes que se atrasan en pagar. "Churn" = clientes que cancelan la suscripcion. Se reserva un % de los ingresos como colchon ante esto.
A26: E. Terminos tecnicos de las APIs
A27: Token | B27: La unidad minima en la que un modelo de lenguaje (Claude, Gemini) lee y escribe texto, aproximadamente ¾ de una palabra en espanol. Se cobra por millon de tokens, separando entrada (lo que el usuario escribe) de salida (lo que el modelo responde).
A28: Credito (ElevenLabs) | B28: La unidad de consumo de la voz de Cost — aproximadamente 1.000 creditos equivalen a 1 minuto de audio generado o transcrito.
A29: Tope (de consumo) | B29: Un limite maximo de gasto configurado directamente en el sistema. A diferencia de una reserva (plata apartada preventivamente), el tope es un freno automatico real: al llegarse, la funcion deja de funcionar hasta el mes siguiente.
A30: Consumo "Normal" vs. "Exagerado" | B30: "Normal" es el uso esperado de un cliente promedio, para presupuestar el gasto real del dia a dia. "Exagerado" es una simulacion deliberada del peor caso realista, usada solo para dimensionar el colchon necesario, nunca como el gasto que se espera de verdad.
A32: Fuente: elaboracion propia a partir de docs/PLAN_COSTOS_COMPLETO_COSTO360.md y la terminologia usada en las Hojas 02 a 09 de este libro.
