Workbook

Sheet Resumen Ejecutivo & Presupuesto
A1: MÉTRICAS CLAVE
A2: TRM (1 USD) | B2: 3128.65
A3: Margen Bruto del Software | B3: 0.82
A4: Costo Marginal por Cotización (Año 1) | B4: =C11/1000 -> 3134.6883
A6: RESUMEN DE COSTOS CONSOLIDADO
A7: Categoría | B7: Costo Mensual USD | C7: Costo Mensual COP | D7: Costo Anual COP
A8: Tokens IA (+50% colchón) | B8: ='Simulación Tokens por Agente'!I8 -> 211.95 | C8: ='Simulación Tokens por Agente'!J8 -> 663117.37 | D8: =C8*12 -> 7957408.4
A9: Herramientas Solicitadas | B9: ='Stack Tecnológico & Infraestruc'!C15 -> 10.33 | C9: ='Stack Tecnológico & Infraestruc'!D15 -> 32318.954 | D9: ='Stack Tecnológico & Infraestruc'!E15 -> 387827.45
A10: Infraestructura Omitida | B10: ='Stack Tecnológico & Infraestruc'!C22 -> 779.65 | C10: ='Stack Tecnológico & Infraestruc'!D22 -> 2439252 | D10: ='Stack Tecnológico & Infraestruc'!E22 -> 29271024
A11: TOTAL GENERAL TECNOLÓGICO | B11: =SUM(B8:B10) -> 1001.93 | C11: =SUM(C8:C10) -> 3134688.3 | D11: =SUM(D8:D10) -> 37616260
A13: CAPACIDAD MÁXIMA DEL INVERSIONISTA | B13: 200000000
A15: ESCENARIOS DE LEVANTAMIENTO DE CAPITAL
A16: Categoría | B16: Escenario 1 (Lean) | C16: Escenario 2 (Recomendado) | D16: Escenario 3 (Acelerado)
A17: Monto Total | B17: 114271648 | C17: 134271648 | D17: 200000000
A18: Runway (Meses) | B18: 12 | C18: 14 | D18: 18
A19: Objetivo Principal | B19: 50-60 clientes | C19: >100 clientes y breakeven | D19: 180 clientes y multi-ciudad
A21: DISTRIBUCIÓN DE FONDOS (COP)
A22: Categoría | B22: Escenario 1 (Lean) | C22: Escenario 2 (Recomendado) | D22: Escenario 3 (Acelerado)
A23: Tecnología | B23: 29271648 | C23: 29271648 | D23: 38000000
A24: Sueldo Fundador | B24: 54000000 | C24: 54000000 | D24: 81000000
A25: Marketing / Ads | B25: 15000000 | C25: 25000000 | D25: 45000000
A26: Legal / SIC / Contador | B26: 8500000 | C26: 11500000 | D26: 16000000
A27: Fondo de Reserva | B27: 7500000 | C27: 14500000 | D27: 20000000
A28: Total | B28: =SUM(B23:B27) -> 114271648 | C28: =SUM(C23:C27) -> 134271648 | D28: =SUM(D23:D27) -> 200000000
A30: DISTRIBUCIÓN DE FONDOS (%)
A31: Categoría | B31: Escenario 1 (Lean) | C31: Escenario 2 (Recomendado) | D31: Escenario 3 (Acelerado)
A32: Tecnología | B32: =B23/B$28 -> 0.25615845 | C32: =C23/C$28 -> 0.21800319 | D32: =D23/D$28 -> 0.19
A33: Sueldo Fundador | B33: =B24/B$28 -> 0.47255816 | C33: =C24/C$28 -> 0.40216979 | D33: =D24/D$28 -> 0.405
A34: Marketing / Ads | B34: =B25/B$28 -> 0.13126616 | C34: =C25/C$28 -> 0.18618972 | D34: =D25/D$28 -> 0.225
A35: Legal / SIC / Contador | B35: =B26/B$28 -> 0.074384155 | C35: =C26/C$28 -> 0.085647269 | D35: =D26/D$28 -> 0.08
A36: Fondo de Reserva | B36: =B27/B$28 -> 0.065633078 | C36: =C27/C$28 -> 0.10799004 | D36: =D27/D$28 -> 0.1
A37: Total | B37: =SUM(B32:B36) -> 1 | C37: =SUM(C32:C36) -> 1 | D37: =SUM(D32:D36) -> 1
A39: MODELO DE MONETIZACIÓN Y UNIT ECONOMICS
A40: Métrica | B40: Valor
A41: Plan Starter | B41: 150000
A42: Plan Pro | B42: 375000
A43: Plan Enterprise | B43: 850000
A44: ARPU Promedio | B44: 333750
A45: MRR a 100 clientes | B45: 33375000
A46: ARR a 100 clientes | B46: 400500000
...

Sheet Simulación Tokens por Agente
A1: Agente | B1: Tarea | C1: Modelo | D1: Requests | E1: Tokens In | F1: Tokens Out | G1: Costo Base USD | H1: Costo Base COP | I1: Costo Colchón USD (+50%) | J1: Costo Colchón COP
A2: Agente 1: Ventas y Prospección Outbound | B2: Calificación de leads, prospección B2B, seguimiento y manejo de objeciones. | C2: Gemini Flash Lite & Claude Sonnet | D2: 10500 | E2: 16500000 | F2: 3675000 | G2: 50.74 | H2: =G2*3128.65 -> 158747.7 | I2: =G2*1.5 -> 76.11 | J2: =I2*3128.65 -> 238121.55
A3: Agente 2: Producto, Nesting 2D y Renderizado | B3: Validación paramétrica de medidas de losas, cálculo de merma, extracción de branding K-Means, BOM. | C3: Gemini Flash Lite & Claude Sonnet | D3: 5500 | E3: 11750000 | F3: 3150000 | G3: 60.49 | H3: =G3*3128.65 -> 189252.04 | I3: =G3*1.5 -> 90.735 | J3: =I3*3128.65 -> 283878.06
A4: Agente 3: Contabilidad, Impuestos y Facturación | B4: Cálculo de AIU, validación RST/ICA, auditoría de retenciones y payload JSON a Alegra. | C4: Gemini Flash Lite & Claude Sonnet | D4: 3000 | E4: 5000000 | F4: 2100000 | G4: 14.21 | H4: =G4*3128.65 -> 44458.116 | I4: =G4*1.5 -> 21.315 | J4: =I4*3128.65 -> 66687.175
A5: Agente 4: Soporte Técnico y Onboarding B2B | B5: Resolución de dudas operativas, tutoriales interactivos y soporte a talleres. | C5: Gemini Flash Lite & Claude Sonnet | D5: 3900 | E5: 4300000 | F5: 1290000 | G5: 6.58 | H5: =G5*3128.65 -> 20586.517 | I5: =G5*1.5 -> 9.87 | J5: =I5*3128.65 -> 30879.775
A6: Agente 5: Marketing y Copywriting | B6: Redacción de correos outbound, guiones de video comercial y copies. | C6: Gemini Flash Lite & Claude Sonnet | D6: 800 | E6: 1650000 | F6: 610000 | G6: 8.23 | H6: =G6*3128.65 -> 25748.789 | I6: =G6*1.5 -> 12.345 | J6: =I6*3128.65 -> 38623.184
A7: Agente 6: Orquestador Transaccional | B7: Enrutamiento determinista entre agentes, supervisión de estado y control de fallbacks. | C7: Gemini Flash Lite | D7: 10000 | E7: 8000000 | F7: 1500000 | G7: 1.05 | H7: =G7*3128.65 -> 3285.0825 | I7: =G7*1.5 -> 1.575 | J7: =I7*3128.65 -> 4927.6237
A8: TOTAL | D8: =SUM(D2:D7) -> 33700 | E8: =SUM(E2:E7) -> 47200000 | F8: =SUM(F2:F7) -> 12325000 | G8: =SUM(G2:G7) -> 141.3 | H8: =SUM(H2:H7) -> 442078.24 | I8: =SUM(I2:I7) -> 211.95 | J8: =SUM(J2:J7) -> 663117.37

Sheet Stack Tecnológico & Infraestruc
A1: Categoría | B1: Herramienta | C1: Costo Mensual USD | D1: Costo Mensual COP | E1: Costo Anual COP
A2: Infraestructura | B2: Tokens IA (+50% colchón) | C2: 211.94 | D2: =C2*3128.65 -> 663086.08 | E2: =D2*12 -> 7957033
A3: Infraestructura | B3: Railway (Docker, Python, WeasyPrint) | C3: 60 | D3: =C3*3128.65 -> 187719 | E3: =D3*12 -> 2252628
A4: Infraestructura | B4: Supabase Pro (Postgres, pgvector, checkpointers) | C4: 35 | D4: =C4*3128.65 -> 109502.75 | E4: =D4*12 -> 1314033
A5: Infraestructura | B5: Alegra API (Facturación DIAN / Contabilidad) | C5: 70.32 | D5: =C5*3128.65 -> 220006.67 | E5: =D5*12 -> 2640080
A6: Infraestructura | B6: Pipedrive CRM (Gestión Leads) | C6: 39 | D6: =C6*3128.65 -> 122017.35 | E6: =D6*12 -> 1464208.2
A7: Infraestructura | B7: Higgsfield Ultra ($99/mes anual) | C7: 99 | D7: =C7*3128.65 -> 309736.35 | E7: =D7*12 -> 3716836.2
A8: Infraestructura | B8: Sentry Team (Errores) | C8: 26 | D8: =C8*3128.65 -> 81344.9 | E8: =D8*12 -> 976138.8
A9: Infraestructura | B9: PostHog (Analítica) | C9: 25 | D9: =C9*3128.65 -> 78216.25 | E9: =D9*12 -> 938595
A10: Infraestructura | B10: Resend Pro (Emails) | C10: 20 | D10: =C10*3128.65 -> 62573 | E10: =D10*12 -> 750876
A11: Infraestructura | B11: Google Workspace (2 cuentas) | C11: 14.4 | D11: =C11*3128.65 -> 45052.56 | E11: =D11*12 -> 540630.72
A12: Infraestructura | B12: Google AI Ultra / Antigravity | C12: 19.99 | D12: =C12*3128.65 -> 62541.713 | E12: =D12*12 -> 750500.56
A13: Infraestructura | B13: Claude Max / Pro | C13: 25 | D13: =C13*3128.65 -> 78216.25 | E13: =D13*12 -> 938595
... A21: Infraestructura | B21: Cloudflare R2 (PDFs y storage) | C21: 5 | D21: =C21*3128.65 -> 15643.25 | E21: =D21*12 -> 187719
A22: TOTAL | B22: TOTAL TECNOLÓGICO | C22: =SUM(C2:C21) -> 779.65 | D22: =SUM(D2:D21) -> 2439252 | E22: =SUM(E2:E21) -> 29271024
A23: TOTAL GENERAL TECNOLÓGICO | C23: =C15+C22 -> 789.98 | D23: =D15+D22 -> 2471570.9 | E23: =E15+E22 -> 29658851

Sheet Proyección a 5 Años
A1: Año | B1: Clientes Activos | C1: MRR (COP) | D1: Ingresos Anuales (COP) | E1: Costo Tech Anual (COP) | F1: Margen Bruto | G1: Hito Operativo
A2: Año 1 | B2: 100 | C2: 33300000 | D2: 185000000 | E2: 29300000 | F2: 0.84 | G2: Automatización total Colombia y PMF.
A3: Año 2 | B3: 250 | C3: 83400000 | D3: 750000000 | E3: 62000000 | F3: 0.89 | G3: Expansión Bogotá, Medellín y Cali.
A4: Año 3 | B4: 650 | C4: 216900000 | D4: 2150000000 | E4: 165000000 | F4: 0.92 | G4: Expansión México y Perú (Multi-divisa).
A5: Año 4 | B5: 1500 | C5: 500600000 | D5: 5200000000 | E5: 360000000 | F5: 0.93 | G5: Red B2B de distribuidores de piedra.
A6: Año 5 | B6: 3200 | C6: 1068000000 | D6: 11500000000 | E6: 720000000 | F6: 0.94 | G6: Consolidación como estándar SaaS en LatAm.
